Workbook

Sheet DCF>

Sheet WACC
L1: TATA MOTORS LTD
B6: Weighted Average Cost of Capital
B8: All figures are in INR unless stated otherwise
B10: Peer Comps
H11: Debt/ | I11: Debt/ | J11: Levered | K11: Unlevered
B12: Name of the Comp | D12: Country | E12: Total debt | F12: Total Equity | G12: Tax Rate1 | H12: Equity | I12: Capital | J12: Beta2 | K12: Beta3
B14: M & M | D14: India | E14: =('[1]Beta Comps'!F7) -> 129024.58 | F14: =('[1]Beta Comps'!E7) -> 398681.24 | G14: 0.25 | H14: =E14/F14 -> 0.32362842 | I14: =E14/(E14+F14) -> 0.24450096 | J14: 1.35 | K14: =J14/(1+(1-G14)*H14) -> 1.0863256
B15: Maruti Suzuki | D15: India | E15: =('[1]Beta Comps'!F8) -> 87 | F15: =('[1]Beta Comps'!E8) -> 396262.16 | G15: 0.25 | H15: =E15/F15 -> 0.00021955162 | I15: =E15/(E15+F15) -> 0.00021950343 | J15: 0.946 | K15: =J15/(1+(1-G15)*H15) -> 0.94584425
B16: Tata Motors | D16: India | E16: =('[1]Beta Comps'!F9) -> 71540 | F16: =('[1]Beta Comps'!E9) -> 245201.84 | G16: 0.25 | H16: =E16/F16 -> 0.29175964 | I16: =E16/(E16+F16) -> 0.22586217 | J16: 1.26 | K16: =J16/(1+(1-G16)*H16) -> 1.033787
B17: Hyundai Motor I | D17: India | E17: =('[1]Beta Comps'!F10) -> 847.29 | F17: =('[1]Beta Comps'!E10) -> 174989.35 | G17: 0.25 | H17: =E17/F17 -> 0.0048419518 | I17: =E17/(E17+F17) -> 0.0048186203 | J17: 0.804 | K17: =J17/(1+(1-G17)*H17) -> 0.80109087
B18: Force Motors | D18: India | E18: =('[1]Beta Comps'!F11) -> 17.43 | F18: =('[1]Beta Comps'!E11) -> 22313.48 | G18: 0.25 | H18: =E18/F18 -> 0.00078114216 | I18: =E18/(E18+F18) -> 0.00078053245 | J18: 0.721 | K18: =J18/(1+(1-G18)*H18) -> 0.72057784
F20: Average | G20: =AVERAGE(G14:G18) -> 0.25 | H20: =AVERAGE(H14:H18) -> 0.12424614 | I20: =AVERAGE(I14:I18) -> 0.095236358 | J20: =AVERAGE(J14:J18) -> 1.0162 | K20: =AVERAGE(K14:K18) -> 0.91752512
F21: Median | G21: =MEDIAN(G14:G18) -> 0.25 | H21: =MEDIAN(H14:H18) -> 0.0048419518 | I21: =MEDIAN(I14:I18) -> 0.0048186203 | J21: =MEDIAN(J14:J18) -> 0.946 | K21: =MEDIAN(K14:K18) -> 0.94584425
B24: Cost of Debt | G24: Cost of Equity
B26: Pre Tax Cost of Debt | E26: =1076/71540 -> 0.015040537 | G26: Risk Free Rate | K26: 0.06376
B27: Tax Rate | E27: 0.25 | G27: Equity Risk Premium | K27: =[1]RM!F10-[1]WACC!K26 -> 0.101988
B28: Post Tax Cost of Debt | E28: =E26*(1-E27) -> 0.011280403 | G28: Levered Beta 4 | K28: =K37 -> 1.0205147
G29: Cost of Equity | K29: =K26+K27*K28 -> 0.16784025
B32: Capital Structure | G32: Levered Beta
D34: Current | E34: Target | G34: Comps Median Unlevered Beta | K34: =K21 -> 0.94584425
B35: Total Debt | C35: =E16 -> 71540 | D35: =C35/$C$37 -> 0.22586217 | E35: =I20 -> 0.095236358 | G35: Target Debt/Equity | K35: =E39 -> 0.10526104
B36: Market Capitalization | C36: =F16 -> 245201.84 | D36: =C36/$C$37 -> 0.77413783 | E36: =E37-E35 -> 0.90476364 | G36: Tax Rate | K36: =G16 -> 0.25
B37: Total Capital | C37: =SUM(C35,C36) -> 316741.84 | D37: =C37/$C$37 -> 1 | E37: =D37 -> 1 | G37: Levered Beta | K37: =K34*(1+(1-K36)*K35) -> 1.0205147
B39: Debt/Equity | D39: =D35/D36 -> 0.29175964 | E39: =E35/E36 -> 0.10526104 | G39: Weighted Average Cost of Capital
B41: Notes | G41: Cost of Equity | K41: =K29 -> 0.16784025
B42: 1. Tax rate are considered as Marginal Tax Rate for the country | G42: Equity Weight | K42: =E36 -> 0.90476364
B43: 2. Levered beta is based on 5 years monthly data
B44: 3. Unlevered beta = Levered beta/(1+(1-Tax Rate)*Debt/Equity | G44: Cost of Debt | K44: =E28 -> 0.011280403
B45: 4. Levered beta = Unlevered beta*(1+(1-Tax Rate)*Debt/Equity | G45: Debt Weight | K45: =E35 -> 0.095236358
G47: WACC | K47: =(K41*K42)+(K44*K45) -> 0.15293006

Sheet Sheet1

Sheet Data>

Sheet Beta Comps
B6: S.No. | C6: Name | D6: CMP Rs. | E6: Mar Cap Rs.Cr. | F6: Debt Rs.Cr. | G6: Debt / Eq
B7: 1 | C7: M & M | D7: 3203.1 | E7: 398681.24 | F7: 129024.58 | G7: 1.67
B8: 2 | C8: Maruti Suzuki | D8: 12608 | E8: 396262.16 | F8: 87 | G8: 0
B9: 3 | C9: Tata Motors | D9: 665.95 | E9: 245201.84 | F9: 71540 | G9: 0.62
B10: 4 | C10: Hyundai Motor I | D10: 2151.8 | E10: 174989.35 | F10: 847.29 | G10: 0.05
B11: 5 | C11: Force Motors | D11: 16944 | E11: 22313.48 | F11: 17.43 | G11: 0.01

Sheet RM
B6: Return on Markets
B8: Year | C8: Annual | E8: Average Return | F8: =AVERAGE(C9:C33) -> 0.153348
B9: 2000 | C9: -0.1465 | E9: Dividend Yield | F9: 0.0124
B10: 2001 | C10: -0.1618 | E10: Total Market Return | F10: =SUM(F8:F9) -> 0.165748
B11: 2002 | C11: 0.0325
B12: 2003 | C12: 0.719
B13: 2004 | C13: 0.1068
B14: 2005 | C14: 0.3634
B15: 2006 | C15: 0.3983
B16: 2007 | C16: 0.5477
B17: 2008 | C17: -0.5179
B18: 2009 | C18: 0.7576
B19: 2010 | C19: 0.1795
B20: 2011 | C20: -0.2462
B21: 2012 | C21: 0.277
B22: 2013 | C22: 0.0676
... B33: 2024 | C33: 0.0875

Sheet Intrinsic Growth
L1: TATA MOTORS LTD
A6: # | B6: Calculation of ROIC | G6: {='Raw FS'!$J$2:N2} -> 44256 | H6: 44621 | I6: 44986 | J6: 45352 | K6: 45717
B8: Current Assets
B9: {='Raw FS'!B36:B37} -> Inventories | G9: {='Raw FS'!J36:N36} -> 36089 | H9: 35240 | I9: 40755 | J9: 47788 | K9: 47269
B10: Trade receivables + | G10: {='Raw FS'!J37:N37} -> 12679 | H10: 12442 | I10: 15738 | J10: 16952 | K10: 13248
B11: {='Raw FS'!B39:B40} -> Loans n Advances | G11: {='Raw FS'!J39:N40} -> 4520 | H11: 4583 | I11: -4029 | J11: -1743 | K11: 7552
B12: Other asset items | G12: 57198 | H12: 57641 | I12: 72461 | J12: 80763 | K12: 50911
B13: Total Current Assets | G13: =SUM(G9:G12) -> 110486 | H13: =SUM(H9:H12) -> 109906 | I13: =SUM(I9:I12) -> 124925 | J13: =SUM(J9:J12) -> 143760 | K13: =SUM(K9:K12) -> 118980
B15: Current Liabilities
B16: {='Raw FS'!B13:B15} -> Trade Payables | G16: {='Raw FS'!J13:N15} -> 76040 | H16: 69750 | I16: 79252 | J16: 93978 | K16: 97368
B17: Advance from Customers | G17: 0 | H17: 0 | I17: 0 | J17: 0 | K17: 0
B18: Other liability items | G18: 66579 | H18: 64030 | I18: 68710 | J18: 75185 | K18: 85311
B19: Total Current Liabilities | G19: =SUM(G16:G18) -> 142619 | H19: =SUM(H16:H18) -> 133780 | I19: =SUM(I16:I18) -> 147962 | J19: =SUM(J16:J18) -> 169163 | K19: =SUM(K16:K18) -> 182679
A21: # | B21: Net Working Capital | G21: =G13-G19 -> -32133 | H21: =H13-H19 -> -23874 | I21: =I13-I19 -> -23037 | J21: =J13-J19 -> -25403 | K21: =K13-K19 -> -63699
B23: Non Current Assets
B24: {='Raw FS'!B19:B27} -> Land | G24: {='Raw FS'!J19:N19} -> 7819 | H24: 7760 | I24: 8045 | J24: 7996 | K24: 7900
B25: Building | G25: {='Raw FS'!J20:N20} -> 35537 | H25: 36466 | I25: 38674 | J25: 40583 | K25: 44662
B26: Plant Machinery | G26: {='Raw FS'!J21:N21} -> 138868 | H26: 148585 | I26: 153672 | J26: 151877 | K26: 155939
B27: Equipments | G27: {='Raw FS'!J22:N22} -> 0 | H27: 0 | I27: 0 | J27: 0 | K27: 0
B28: Computers | G28: {='Raw FS'!J23:N23} -> 3172 | H28: 3383 | I28: 3499 | J28: 3667 | K28: 3879
B29: Furniture n fittings | G29: {='Raw FS'!J24:N24} -> 1956 | H29: 1984 | I29: 2084 | J29: 2029 | K29: 1970
B30: Vehicles | G30: {='Raw FS'!J25:N25} -> 845 | H30: 725 | I30: 788 | J30: 956 | K30: 1151
B31: Intangible Assets | G31: {='Raw FS'!J26:N26} -> 114809 | H31: 114323 | I31: 112538 | J31: 116714 | K31: 93455
B32: Other fixed assets | G32: {='Raw FS'!J27:N27} -> 10686 | H32: 10870 | I32: 11841 | J32: 10657 | K32: 11044
B34: ='Raw FS'!B28 -> Gross Block | G34: {='Raw FS'!J28:N28} -> 313692 | H34: 324096 | I34: 331141 | J34: 334479 | K34: 320000
B35: Accumulated Depreciation | G35: {=-'Raw FS'!J29:N29} -> -174985 | H35: -185241 | I35: -199062 | J35: -213194 | K35: -204303
A36: # | B36: Net Non Current Assets | G36: =SUM(G34:G35) -> 138707 | H36: =SUM(H34:H35) -> 138855 | I36: =SUM(I34:I35) -> 132079 | J36: =SUM(J34:J35) -> 121285 | K36: =SUM(K34:K35) -> 115697
A38: # | B38: Invested Capital | G38: =G36+G21 -> 106574 | H38: =H36+H21 -> 114981 | I38: =I36+I21 -> 109042 | J38: =J36+J21 -> 95882 | K38: =K36+K21 -> 51998
B39: EBIT | G39: ='Historical FS'!H27+'Historical FS'!H21 -> 25144.43 | H39: ='Historical FS'!I27+'Historical FS'!I21 -> 18146.09 | I39: ='Historical FS'!J27+'Historical FS'!J21 -> 25810.8 | J39: ='Historical FS'!K27+'Historical FS'!K21 -> 52425 | K39: ='Historical FS'!L27+'Historical FS'!L21 -> 49921
A41: # | B41: ROIC | G41: =G39/G38 -> 0.235934 | H41: =H39/H38 -> 0.15781816 | I41: =I39/I38 -> 0.23670512 | J41: =J39/J38 -> 0.54676582 | K41: =K39/K38 -> 0.96005616
A43: # | B43: Calculation of Reinvestment Rate | G43: =G6 -> 44256 | H43: =H6 -> 44621 | I43: =I6 -> 44986 | J43: =J6 -> 45352 | K43: =K6 -> 45717
B45: Net Capex | G45: =-SUM('Raw FS'!J56:J57) -> 19854 | H45: =-SUM('Raw FS'!K56:K57) -> 14938 | I45: =-SUM('Raw FS'!L56:L57) -> 18945 | J45: =-SUM('Raw FS'!M56:M57) -> 31183 | K45: =-SUM('Raw FS'!N56:N57) -> 37068
B46: Change in Working Capital | H46: =H21-G21 -> 8259 | I46: =I21-H21 -> 837 | J46: =J21-I21 -> -2366 | K46: =K21-J21 -> -38296
B48: EBIT | G48: =G39 -> 25144.43 | H48: =H39 -> 18146.09 | I48: =I39 -> 25810.8 | J48: =J39 -> 52425 | K48: =K39 -> 49921
B49: Marginal Tax Rate | G49: 0.25 | H49: 0.25 | I49: 0.25 | J49: 0.25 | K49: 0.25
B50: EBIT(1-T) | G50: =G48*(1-G49) -> 18858.322 | H50: =H48*(1-H49) -> 13609.568 | I50: =I48*(1-I49) -> 19358.1 | J50: =J48*(1-J49) -> 39318.75 | K50: =K48*(1-K49) -> 37440.75
B52: Reinvestment | H52: =SUM(H45:H46) -> 23197 | I52: =SUM(I45:I46) -> 19782 | J52: =SUM(J45:J46) -> 28817 | K52: =SUM(K45:K46) -> -1228
B54: Reinvestment Rate | H54: =H52/H50 -> 1.7044627 | I54: =I52/I50 -> 1.0218978 | J54: =J52/J50 -> 0.73290733 | K54: =K52/K50 -> -0.032798488
J56: 4 Year Average | K56: =AVERAGE(H54:K54) -> 0.85661733
J57: 4 Year Median | K57: =MEDIAN(H54:K54) -> 0.87740257
...

Sheet DCF
L1: TATA MOTORS LTD
B6: Calculation of PV of FCFF | F6: ='Intrinsic Growth'!K6 -> 45717 | G6: =F6+365 -> 46082 | H6: =G6+365 -> 46447 | I6: =H6+366 -> 46813 | J6: =I6+365 -> 47178 | K6: =J6+365 -> 47543
B8: EBIT | F8: ='Intrinsic Growth'!K39 -> 49921 | G8: =F8*(1+$D$25) -> 50225.518 | H8: =G8*(1+$D$25) -> 50531.894 | I8: =H8*(1+$D$25) -> 50840.138 | J8: =I8*(1+$D$25) -> 51150.263 | K8: =J8*(1+$D$25) -> 51462.28
B10: Tax Rate | F10: =25% -> 0.25 | G10: =25% -> 0.25 | H10: =25% -> 0.25 | I10: =25% -> 0.25 | J10: =25% -> 0.25 | K10: =25% -> 0.25
B12: EBIT (1-Tax) | F12: =F8*(1-F10) -> 37440.75 | G12: =G8*(1-G10) -> 37669.139 | H12: =H8*(1-H10) -> 37898.92 | I12: =I8*(1-I10) -> 38130.104 | J12: =J8*(1-J10) -> 38362.697 | K12: =K8*(1-K10) -> 38596.71
B14: Less: Reinvestment Rate | F14: ='Intrinsic Growth'!K57 -> 0.87740257 | G14: =F14+(($K$14-$F$14)/4) -> 0.66825193 | H14: =G14+(($K$14-$F$14)/4) -> 0.45910128 | I14: =H14+(($K$14-$F$14)/4) -> 0.24995064 | J14: =I14+(($K$14-$F$14)/4) -> 0.0408 | K14: 0.0408
B16: Free Cash Flow to Firm (FCFF) | F16: =F12*(1-F14) -> 4590.1398 | G16: =G12*(1-G14) -> 12496.664 | H16: =H12*(1-H14) -> 20499.477 | I16: =I12*(1-I14) -> 28599.46 | J16: =J12*(1-J14) -> 36797.499 | K16: =K12*(1-K14) -> 37021.964
B18: Mid Year Convention | G18: 0.5 | H18: =G18+1 -> 1.5 | I18: =H18+1 -> 2.5 | J18: =I18+1 -> 3.5 | K18: =J18+1 -> 4.5
B20: Discounting Factor | G20: =1/(1+$D$27)^G18 -> 0.93131912 | H20: =1/(1+$D$27)^H18 -> 0.80778458 | I20: =1/(1+$D$27)^I18 -> 0.70063623 | J20: =1/(1+$D$27)^J18 -> 0.60770055 | K20: =1/(1+$D$27)^K18 -> 0.5270923
B22: PV of FCFF | G22: =G16*G20 -> 11638.382 | H22: =H16*H20 -> 16559.162 | I22: =I16*I20 -> 20037.818 | J22: =J16*J20 -> 22361.861 | K22: =K16*K20 -> 19513.992
B25: Expected Growth | D25: 0.0061
B26: Terminal Growth | D26: 0.065
B27: WACC | D27: =WACC!K47 -> 0.15293006
B30: Calculation of Terminal Value
B32: FCFF(n+1) | D32: =K16*(1+D25) -> 37247.798
B33: WACC | D33: =D27 -> 0.15293006
B34: Terminal Growth Rate | D34: =D26 -> 0.065
B36: Terminal Value | D36: =D32/(D33-D34) -> 423607.1
B38: Calcultion of Equity Value Per Share
B40: PV of FCFF | D40: =SUM(G22:K22) -> 90111.214
B41: PV of Terminal Value | D41: =D36*K20 -> 223280.04
B42: Value of Operating Assets (EV) | D42: =SUM(D40:D41) -> 313391.26
B44: Add Cash | D44: ='Data Sheet'!K69 -> 40834
B45: Less Debt | D45: =SUM('Raw FS'!N7:N8) -> 62499
B46: Value of Equity | D46: =D42+D44-D45 -> 291726.26
B47: No. of Shares | D47: ='Data Sheet'!B6 -> 368.17104
B49: Equity Value Per Share | D49: =D46/D47 -> 792.36611
B51: Share Price | D51: 649
B52: Discount/Premium | D52: =D51/D49-1 -> -0.18093418

Sheet Raw FS
B2: Particulars | C2: 41699 | D2: 42064 | E2: 42430 | F2: 42795 | G2: 43160 | H2: 43525 | I2: 43891 | J2: 44256 | K2: 44621 | L2: 44986 | M2: 45352 | N2: 45717
B4: Equity Capital | C4: 644 | D4: 644 | E4: 679 | F4: 679 | G4: 679 | H4: 679 | I4: 720 | J4: 766 | K4: 766 | L4: 766 | M4: 767 | N4: 736
B5: Reserves | C5: 64960 | D5: 55618 | E5: 78273 | F5: 57383 | G5: 94749 | H5: 59500 | I5: 62359 | J5: 54481 | K5: 43795 | L5: 44556 | M5: 84151 | N5: 115408
B6: Borrowings -
B7: Long term Borrowings | C7: 45259 | D7: 56071 | E7: 50510 | F7: 60629 | G7: 61200 | H7: 70818 | I7: 83316 | J7: 93113 | K7: 97759 | L7: 88696 | M7: 62149 | N7: 40217
B8: Short term Borrowings | C8: 9696 | D8: 13140 | E8: 11451 | F8: 13860 | G8: 16795 | H8: 20150 | I8: 16363 | J8: 42792 | K8: 41918 | L8: 36965 | M8: 36352 | N8: 22282
B9: Lease Liabilities | C9: 0 | D9: 0 | E9: 0 | F9: 0 | G9: 0 | H9: 173 | I9: 5977 | J9: 6226 | K9: 6772 | L9: 8453 | M9: 8763 | N9: 9041
B10: Other Borrowings | C10: 5688 | D10: 4399 | E10: 7399 | F10: 4115 | G10: 10956 | H10: 15034 | I10: 19132 | J10: 0 | K10: 0 | L10: 0 | M10: 0 | N10: 0
B11: Other Liabilities -
B12: Non controlling int | C12: 421 | D12: 433 | E12: 433 | F12: 453 | G12: 525 | H12: 523 | I12: 814 | J12: 1573 | K12: 4271 | L12: 7278 | M12: 8176 | N12: 6610
B13: Trade Payables | C13: 57316 | D13: 57407 | E13: 61562 | F13: 62533 | G13: 76940 | H13: 71691 | I13: 66398 | J13: 76040 | K13: 69750 | L13: 79252 | M13: 93978 | N13: 97368
B14: Advance from Customers | C14: 3119 | D14: 2289 | E14: 2165 | F14: 1711 | G14: 0 | H14: 0 | I14: 0 | J14: 0 | K14: 0 | L14: 0 | M14: 0 | N14: 0
B15: Other liability items | C15: 31325 | D15: 47313 | E15: 50712 | F15: 71218 | G15: 65349 | H15: 67135 | I15: 65101 | J15: 66579 | K15: 64030 | L15: 68710 | M15: 75185 | N15: 85311
B16: Total Liabilities | C16: 218426 | D16: 237315 | E16: 263184 | F16: 272580 | G16: 327192 | H16: 305703 | I16: 320179 | J16: 341570 | K16: 329061 | L16: 334674 | M16: 369521 | N16: 376973
B18: Fixed Assets -
B19: Land | C19: 2296 | D19: 2513 | E19: 7185 | F19: 6762 | G19: 7339 | H19: 7286 | I19: 7675 | J19: 7819 | K19: 7760 | L19: 8045 | M19: 7996 | N19: 7900
B20: Building | C20: 11010 | D20: 13396 | E20: 12343 | F20: 12164 | G20: 16552 | H20: 22938 | I20: 32665 | J20: 35537 | K20: 36466 | L20: 38674 | M20: 40583 | N20: 44662
B21: Plant Machinery | C21: 79505 | D21: 88943 | E21: 80063 | F21: 79976 | G21: 100226 | H21: 109415 | I21: 124158 | J21: 138868 | K21: 148585 | L21: 153672 | M21: 151877 | N21: 155939
B22: Equipments | C22: 0 | D22: 482 | E22: 498 | F22: 0 | G22: 0 | H22: 0 | I22: 0 | J22: 0 | K22: 0 | L22: 0 | M22: 0 | N22: 0
B23: Computers | C23: 1126 | D23: 1364 | E23: 1634 | F23: 1767 | G23: 1943 | H23: 2335 | I23: 3054 | J23: 3172 | K23: 3383 | L23: 3499 | M23: 3667 | N23: 3879
B24: Furniture n fittings | C24: 1011 | D24: 1149 | E24: 1241 | F24: 1401 | G24: 1430 | H24: 1626 | I24: 1890 | J24: 1956 | K24: 1984 | L24: 2084 | M24: 2029 | N24: 1970
B25: Vehicles | C25: 270 | D25: 280 | E25: 280 | F25: 291 | G25: 353 | H25: 387 | I25: 601 | J25: 845 | K25: 725 | L25: 788 | M25: 956 | N25: 1151
B26: Intangible Assets | C26: 8994 | D26: 9580 | E26: 58951 | F26: 54932 | G26: 77870 | H26: 80480 | I26: 91157 | J26: 114809 | K26: 114323 | L26: 112538 | M26: 116714 | N26: 93455
B27: Other fixed assets | C27: 33694 | D27: 45196 | E27: 6746 | F27: 6219 | G27: 7497 | H27: 8049 | I27: 9380 | J27: 10686 | K27: 10870 | L27: 11841 | M27: 10657 | N27: 11044
B28: Gross Block | C28: 137907 | D28: 162904 | E28: 168941 | F28: 163512 | G28: 213209 | H28: 232517 | I28: 270579 | J28: 313692 | K28: 324096 | L28: 331141 | M28: 334479 | N28: 320000
B29: Accumulated Depreciation | C29: 68815 | D29: 74424 | E29: 61709 | F29: 67568 | G29: 91795 | H29: 121283 | I29: 143471 | J29: 174985 | K29: 185241 | L29: 199062 | M29: 213194 | N29: 204303
B30: Net Block | C30: =C28-C29 -> 69092 | D30: =D28-D29 -> 88480 | E30: =E28-E29 -> 107232 | F30: =F28-F29 -> 95944 | G30: =G28-G29 -> 121414 | H30: =H28-H29 -> 111234 | I30: =I28-I29 -> 127108 | J30: =J28-J29 -> 138707 | ... N30: =N28-N29 -> 115697
B32: CWIP | C32: 33263 | D32: 28640 | E32: 25919 | F32: 33699 | G32: 40034 | H32: 31884 | I32: 35622 | J32: 20964 | K32: 10251 | L32: 14274 | M32: 35698 | N32: 65806
B33: Investments | C33: 10687 | D33: 15337 | E33: 23767 | F33: 20338 | G33: 20813 | H33: 15771 | I33: 16308 | J33: 24620 | K33: 29380 | L33: 26379 | M33: 22971 | N33: 35656
B35: Other Assets -
B36: Inventories | C36: 27271 | D36: 29272 | E36: 32656 | F36: 35085 | G36: 42138 | H36: 39014 | I36: 37457 | J36: 36089 | K36: 35240 | L36: 40755 | M36: 47788 | N36: 47269
B37: Trade receivables + | C37: 10574 | D37: 12579 | E37: 13571 | F37: 14076 | G37: 19893 | H37: 18996 | I37: 11173 | J37: 12679 | K37: 12442 | L37: 15738 | M37: 16952 | N37: 13248
B38: Cash Equivalents | C38: 29712 | D38: 32116 | E38: 30460 | F38: 36078 | G38: 34614 | H38: 32649 | I38: 33727 | J38: 46792 | K38: 40669 | L38: 37016 | M38: 45807 | N38: 40834
B39: Loans n Advances | C39: 9953 | D39: 6628 | E39: 2072 | F39: 1816 | G39: 4066 | H39: 3620 | I39: 3353 | J39: 4520 | K39: 4583 | L39: -4029 | M39: -1743 | N39: 7552
B40: Other asset items | C40: 27876 | D40: 24263 | E40: 27508 | F40: 35544 | G40: 44221 | H40: 52535 | I40: 55432 | J40: 57198 | K40: 57641 | L40: 72461 | M40: 80763 | N40: 50911
B41: Total Assets | C41: 218426 | D41: 237315 | E41: 263184 | F41: 272580 | G41: 327192 | H41: 305703 | I41: 320179 | J41: 341570 | K41: 329061 | L41: 334674 | M41: 369521 | N41: 376973
B45: Particulars | C45: 41699 | D45: 42064 | E45: 42430 | F45: 42795 | G45: 43160 | H45: 43525 | I45: 43891 | J45: 44256 | K45: 44621 | L45: 44986 | M45: 45352 | N45: 45717
B46: Cash from Operating Activity - | C46: 36151 | D46: 35531 | E46: 37900 | F46: 30199 | G46: 23857 | H46: 18891 | I46: 26633 | J46: 29001 | K46: 14283 | L46: 35388 | M46: 67915 | N46: 63102
B47: Profit from operations | C47: 36303 | D47: 43397 | E47: 38626 | F47: 28840 | G47: 33312 | H47: 28771 | I47: 23352 | J47: 31198 | K47: 26943 | L47: 41694 | M47: 65106 | N47: 58937
B48: Receivables | C48: 445 | D48: -3179 | E48: -2223 | F48: -4152 | G48: -10688 | H48: -9109 | I48: 9950 | J48: -5505 | K48: 185 | L48: -2213 | M48: -1876 | N48: 3573
...

Sheet Historical FS
B2: ="Historical Financial Statements - "&'Data Sheet'!B1 -> Historical Financial Statements - TATA MOTORS LTD
B3: Years | C3: ='Data Sheet'!B16 -> 42460 | D3: ='Data Sheet'!C16 -> 42825 | E3: ='Data Sheet'!D16 -> 43190 | F3: ='Data Sheet'!E16 -> 43555 | G3: ='Data Sheet'!F16 -> 43921 | H3: ='Data Sheet'!G16 -> 44286 | I3: ='Data Sheet'!H16 -> 44651 | J3: ='Data Sheet'!I16 -> 45016 | ... L3: ='Data Sheet'!K16 -> 45747 | M3: LTM
A5: # | B5: Income Statement
B6: Sales | C6: =IFERROR('Data Sheet'!B17,0) -> 273045.6 | D6: =IFERROR('Data Sheet'!C17,0) -> 269692.51 | E6: =IFERROR('Data Sheet'!D17,0) -> 291550.48 | F6: =IFERROR('Data Sheet'!E17,0) -> 301938.4 | G6: =IFERROR('Data Sheet'!F17,0) -> 261067.97 | H6: =IFERROR('Data Sheet'!G17,0) -> 249794.75 | I6: =IFERROR('Data Sheet'!H17,0) -> 278453.62 | J6: =IFERROR('Data Sheet'!I17,0) -> 345966.97 | ... L6: =IFERROR('Data Sheet'!K17,0) -> 439695 | M6: =IFERROR(SUM('Data Sheet'!H42:K42),0) -> 441609
B7: Sales Growth | D7: =D6/C6-1 -> -0.01228033 | E7: =E6/D6-1 -> 0.081047746 | F7: =F6/E6-1 -> 0.035629919 | G7: =G6/F6-1 -> -0.13536016 | H7: =H6/G6-1 -> -0.043181168 | I7: =I6/H6-1 -> 0.11472967 | J7: =J6/I6-1 -> 0.24245815 | K7: =K6/J6-1 -> 0.25450126 | ... M7: =M6/L6-1 -> 0.0043530174
B9: COGS | C9: =IFERROR(SUM('Data Sheet'!B18,'Data Sheet'!B20:B22)-1*'Data Sheet'!B19,0) -> 205509.07 | D9: =IFERROR(SUM('Data Sheet'!C18,'Data Sheet'!C20:C22)-1*'Data Sheet'!C19,0) -> 205454.24 | E9: =IFERROR(SUM('Data Sheet'!D18,'Data Sheet'!D20:D22)-1*'Data Sheet'!D19,0) -> 228429.83 | F9: =IFERROR(SUM('Data Sheet'!E18,'Data Sheet'!E20:E22)-1*'Data Sheet'!E19,0) -> 242845.53 | G9: =IFERROR(SUM('Data Sheet'!F18,'Data Sheet'!F20:F22)-1*'Data Sheet'!F19,0) -> 210376.07 | H9: =IFERROR(SUM('Data Sheet'!G18,'Data Sheet'!G20:G22)-1*'Data Sheet'!G19,0) -> 195326.04 | I9: =IFERROR(SUM('Data Sheet'!H18,'Data Sheet'!H20:H22)-1*'Data Sheet'!H19,0) -> 223300.01 | J9: =IFERROR(SUM('Data Sheet'!I18,'Data Sheet'!I20:I22)-1*'Data Sheet'!I19,0) -> 274403.64 | ... L9: =IFERROR(SUM('Data Sheet'!K18,'Data Sheet'!K20:K22)-1*'Data Sheet'!K19,0) -> 340809 | M9: =IFERROR(SUM('Data Sheet'!H43:K43),0) -> 384424
B10: COGS % Sales | C10: =C9/C6 -> 0.75265476 | D10: =D9/D6 -> 0.76180922 | E10: =E9/E6 -> 0.7835001 | F10: =F9/F6 -> 0.80428833 | G10: =G9/G6 -> 0.80582873 | H10: =H9/H6 -> 0.78194614 | I10: =I9/I6 -> 0.80192892 | J10: =J9/J6 -> 0.79314982 | ... M10: =M9/M6 -> 0.87050762
B12: Gross Profit | C12: =C6-C9 -> 67536.53 | D12: =D6-D9 -> 64238.27 | E12: =E6-E9 -> 63120.65 | F12: =F6-F9 -> 59092.87 | G12: =G6-G9 -> 50691.9 | H12: =H6-H9 -> 54468.71 | I12: =I6-I9 -> 55153.61 | J12: =J6-J9 -> 71563.33 | ... M12: =M6-M9 -> 57185
B13: Gross Margin | C13: =C12/C6 -> 0.24734524 | D13: =D12/D6 -> 0.23819078 | E13: =E12/E6 -> 0.2164999 | F13: =F12/F6 -> 0.19571167 | G13: =G12/G6 -> 0.19417127 | H13: =H12/H6 -> 0.21805386 | I13: =I12/I6 -> 0.19807108 | J13: =J12/J6 -> 0.20685018 | ... M13: =M12/M6 -> 0.12949238
B15: Sales and General Expenses | C15: =IFERROR(SUM('Data Sheet'!B23:B24),0) -> 29141.28 | D15: =IFERROR(SUM('Data Sheet'!C23:C24),0) -> 34649.58 | E15: =IFERROR(SUM('Data Sheet'!D23:D24),0) -> 31662.97 | F15: =IFERROR(SUM('Data Sheet'!E23:E24),0) -> 34428.54 | G15: =IFERROR(SUM('Data Sheet'!F23:F24),0) -> 32704.83 | H15: =IFERROR(SUM('Data Sheet'!G23:G24),0) -> 22181.28 | I15: =IFERROR(SUM('Data Sheet'!H23:H24),0) -> 30433.52 | J15: =IFERROR(SUM('Data Sheet'!I23:I24),0) -> 39747.53 | ... L15: =IFERROR(SUM('Data Sheet'!K23:K24),0) -> 43670
B16: S&G Exp % Sales | C16: =C15/C6 -> 0.10672679 | D16: =D15/D6 -> 0.1284781 | E16: =E15/E6 -> 0.10860202 | F16: =F15/F6 -> 0.11402505 | G16: =G15/G6 -> 0.12527324 | H16: =H15/H6 -> 0.088798023 | I16: =I15/I6 -> 0.10929475 | J16: =J15/J6 -> 0.11488822 | ... M16: =M15/M6 -> 0
B18: EBITDA | C18: =C12-C15 -> 38395.25 | D18: =D12-D15 -> 29588.69 | E18: =E12-E15 -> 31457.68 | F18: =F12-F15 -> 24664.33 | G18: =G12-G15 -> 17987.07 | H18: =H12-H15 -> 32287.43 | I18: =I12-I15 -> 24720.09 | J18: =J12-J15 -> 31815.8 | ... L18: =L12-L15 -> 55216
B19: EBITDA Margin | C19: =C18/C6 -> 0.14061845 | D19: =D18/D6 -> 0.10971269 | E19: =E18/E6 -> 0.10789788 | F19: =F18/F6 -> 0.081686629 | G19: =G18/G6 -> 0.068898034 | H19: =H18/H6 -> 0.12925584 | I19: =I18/I6 -> 0.088776328 | J19: =J18/J6 -> 0.091961958 | ... M19: =M18/M6 -> 0
B21: Interest | C21: =IFERROR('Data Sheet'!B27,0) -> 4889.08 | D21: =IFERROR('Data Sheet'!C27,0) -> 4238.01 | E21: =IFERROR('Data Sheet'!D27,0) -> 4681.79 | F21: =IFERROR('Data Sheet'!E27,0) -> 5758.6 | G21: =IFERROR('Data Sheet'!F27,0) -> 7243.33 | H21: =IFERROR('Data Sheet'!G27,0) -> 8097.17 | I21: =IFERROR('Data Sheet'!H27,0) -> 9311.86 | J21: =IFERROR('Data Sheet'!I27,0) -> 10225.48 | ... L21: =IFERROR('Data Sheet'!K27,0) -> 5083 | M21: =IFERROR(SUM('Data Sheet'!H46:K46),0) -> 6317
B22: Interest % Sales | C22: =C21/C6 -> 0.017905727 | D22: =D21/D6 -> 0.01571423 | E22: =E21/E6 -> 0.016058248 | F22: =F21/F6 -> 0.019072102 | G22: =G21/G6 -> 0.027744997 | H22: =H21/H6 -> 0.032415293 | I22: =I21/I6 -> 0.033441332 | J22: =J21/J6 -> 0.029556232 | ... M22: =M21/M6 -> 0.014304509
B24: Depreciation | C24: =IFERROR('Data Sheet'!B45,0) -> 6071.78 | D24: =IFERROR('Data Sheet'!C45,0) -> 7050.2 | E24: =IFERROR('Data Sheet'!D45,0) -> 6633 | F24: =IFERROR('Data Sheet'!E45,0) -> 6637 | G24: =IFERROR('Data Sheet'!F45,0) -> 6850 | H24: =IFERROR('Data Sheet'!G45,0) -> 7143 | I24: =IFERROR('Data Sheet'!H45,0) -> 6574 | J24: =IFERROR('Data Sheet'!I45,0) -> 6005 | ... L24: =IFERROR('Data Sheet'!K45,0) -> 5295 | M24: =IFERROR(SUM('Data Sheet'!H45:K45),0) -> 23273
B25: Depreciation % Sales | C25: =C24/C6 -> 0.022237238 | D25: =D24/D6 -> 0.026141623 | E25: =E24/E6 -> 0.022750777 | F25: =F24/F6 -> 0.021981305 | G25: =G24/G6 -> 0.026238378 | H25: =H24/H6 -> 0.028595477 | I25: =I24/I6 -> 0.023608959 | J25: =J24/J6 -> 0.017357148 | ... M25: =M24/M6 -> 0.052700466
B27: Earning Before Tax | C27: =IFERROR(C18-SUM(C21,C24),0) -> 27434.39 | D27: =IFERROR(D18-SUM(D21,D24),0) -> 18300.48 | E27: =IFERROR(E18-SUM(E21,E24),0) -> 20142.89 | F27: =IFERROR(F18-SUM(F21,F24),0) -> 12268.73 | G27: =IFERROR(G18-SUM(G21,G24),0) -> 3893.74 | H27: =IFERROR(H18-SUM(H21,H24),0) -> 17047.26 | I27: =IFERROR(I18-SUM(I21,I24),0) -> 8834.23 | J27: =IFERROR(J18-SUM(J21,J24),0) -> 15585.32 | ... M27: =IFERROR(M18-SUM(M21,M24),0) -> -29590
B28: EBT % Sales | C28: =C27/C6 -> 0.10047549 | D28: =D27/D6 -> 0.067856834 | E28: =E27/E6 -> 0.069088859 | F28: =F27/F6 -> 0.040633222 | G28: =G27/G6 -> 0.01491466 | H28: =H27/H6 -> 0.068245069 | I28: =I27/I6 -> 0.031726038 | J28: =J27/J6 -> 0.045048578 | ... M28: =M27/M6 -> -0.067004975
B30: Tax | C30: =IFERROR('Data Sheet'!B48,0) -> 262.83 | D30: =IFERROR('Data Sheet'!C48,0) -> -620.65 | E30: =IFERROR('Data Sheet'!D48,0) -> 1563 | F30: =IFERROR('Data Sheet'!E48,0) -> 2203 | G30: =IFERROR('Data Sheet'!F48,0) -> 542 | H30: =IFERROR('Data Sheet'!G48,0) -> -8219 | I30: =IFERROR('Data Sheet'!H48,0) -> 3178 | J30: =IFERROR('Data Sheet'!I48,0) -> 2317 | ... L30: =IFERROR('Data Sheet'!K48,0) -> 2948 | M30: =IFERROR(SUM('Data Sheet'!H48:K48),0) -> 10563
B31: Effective Tax Rate | C31: =C30/C27 -> 0.0095803114 | D31: =D30/D27 -> -0.033914411 | E31: =E30/E27 -> 0.077595618 | F31: =F30/F27 -> 0.17956219 | G31: =G30/G27 -> 0.13919779 | H31: =H30/H27 -> -0.48213027 | I31: =I30/I27 -> 0.35973707 | J31: =J30/J27 -> 0.14866554 | ... M31: =M30/M27 -> -0.35697871
B33: Net Profit | C33: =C27-C30 -> 27171.56 | D33: =D27-D30 -> 18921.13 | E33: =E27-E30 -> 18579.89 | F33: =F27-F30 -> 10065.73 | G33: =G27-G30 -> 3351.74 | H33: =H27-H30 -> 25266.26 | I33: =I27-I30 -> 5656.23 | J33: =J27-J30 -> 13268.32 | ... M33: =M27-M30 -> -40153
B34: Net Margin | C34: =C33/C6 -> 0.099512902 | D34: =D33/D6 -> 0.070158159 | E34: =E33/E6 -> 0.063727866 | F34: =F33/F6 -> 0.033337032 | G34: =G33/G6 -> 0.012838572 | H34: =H33/H6 -> 0.10114808 | I34: =I33/I6 -> 0.020313006 | J34: =J33/J6 -> 0.038351407 | ... M34: =M33/M6 -> -0.090924324
B36: No. of Equity Shares | C36: =IFERROR('Data Sheet'!B93,0) -> 288.72 | D36: =IFERROR('Data Sheet'!C93,0) -> 288.73 | E36: =IFERROR('Data Sheet'!D93,0) -> 288.73 | F36: =IFERROR('Data Sheet'!E93,0) -> 288.73 | G36: =IFERROR('Data Sheet'!F93,0) -> 308.9 | H36: =IFERROR('Data Sheet'!G93,0) -> 332.03 | I36: =IFERROR('Data Sheet'!H93,0) -> 332.07 | J36: =IFERROR('Data Sheet'!I93,0) -> 332.13 | ... M36: =IFERROR('Data Sheet'!L93,0) -> 0
B38: Earnings Per Share | C38: =IFERROR(C33/C36,0) -> 94.110418 | D38: =IFERROR(D33/D36,0) -> 65.532262 | E38: =IFERROR(E33/E36,0) -> 64.350397 | F38: =IFERROR(F33/F36,0) -> 34.862086 | G38: =IFERROR(G33/G36,0) -> 10.850567 | H38: =IFERROR(H33/H36,0) -> 76.096317 | I38: =IFERROR(I33/I36,0) -> 17.033246 | J38: =IFERROR(J33/J36,0) -> 39.949177 | ... M38: =IFERROR(M33/M36,0) -> 0
B39: EPS Growth % | D39: =IFERROR(D38/C38-1,0) -> -0.30366623 | E39: =IFERROR(E38/D38-1,0) -> -0.018034864 | F39: =IFERROR(F38/E38-1,0) -> -0.45824599 | G39: =IFERROR(G38/F38-1,0) -> -0.68875739 | H39: =IFERROR(H38/G38-1,0) -> 6.0131192 | I39: =IFERROR(I38/H38-1,0) -> -0.77616202 | J39: =IFERROR(J38/I38-1,0) -> 1.3453649 | K39: =IFERROR(K38/J38-1,0) -> 2.2166965 | ... M39: =IFERROR(M38/L38-1,0) -> -1
B41: Dividend Per Share | C41: =IFERROR('Data Sheet'!B31/'Historical FS'!C36,0) -> 0.23524522 | D41: =IFERROR('Data Sheet'!C31/'Historical FS'!D36,0) -> 0 | E41: =IFERROR('Data Sheet'!D31/'Historical FS'!E36,0) -> 0 | F41: =IFERROR('Data Sheet'!E31/'Historical FS'!F36,0) -> 0 | G41: =IFERROR('Data Sheet'!F31/'Historical FS'!G36,0) -> 0 | H41: =IFERROR('Data Sheet'!G31/'Historical FS'!H36,0) -> 0 | I41: =IFERROR('Data Sheet'!H31/'Historical FS'!I36,0) -> 0 | J41: =IFERROR('Data Sheet'!I31/'Historical FS'!J36,0) -> 2.3063861 | ... M41: =IFERROR('Data Sheet'!L31/'Historical FS'!M36,0) -> 0
B42: Dividend Payout Ratio | C42: =IFERROR(C41/C38,0) -> 0.0024996725 | D42: =IFERROR(D41/D38,0) -> 0 | E42: =IFERROR(E41/E38,0) -> 0 | F42: =IFERROR(F41/F38,0) -> 0 | G42: =IFERROR(G41/G38,0) -> 0 | H42: =IFERROR(H41/H38,0) -> 0 | I42: =IFERROR(I41/I38,0) -> 0 | J42: =IFERROR(J41/J38,0) -> 0.057733006 | ... M42: =IFERROR(M41/M38,0) -> 0
B44: Retained Earnings | C44: =IFERROR(IF(C38>C41,1-C42,0),0) -> 0.99750033 | D44: =IFERROR(IF(D38>D41,1-D42,0),0) -> 1 | E44: =IFERROR(IF(E38>E41,1-E42,0),0) -> 1 | F44: =IFERROR(IF(F38>F41,1-F42,0),0) -> 1 | G44: =IFERROR(IF(G38>G41,1-G42,0),0) -> 1 | H44: =IFERROR(IF(H38>H41,1-H42,0),0) -> 1 | I44: =IFERROR(IF(I38>I41,1-I42,0),0) -> 1 | J44: =IFERROR(IF(J38>J41,1-J42,0),0) -> 0.94226699 | ... M44: =IFERROR(IF(M38>M41,1-M42,0),0) -> 0
B46: Balance Sheet
B47: Equity Share Capital | C47: =IFERROR('Data Sheet'!B57,0) -> 679.18 | D47: =IFERROR('Data Sheet'!C57,0) -> 679.22 | E47: =IFERROR('Data Sheet'!D57,0) -> 679.22 | F47: =IFERROR('Data Sheet'!E57,0) -> 679.22 | G47: =IFERROR('Data Sheet'!F57,0) -> 719.54 | H47: =IFERROR('Data Sheet'!G57,0) -> 765.81 | I47: =IFERROR('Data Sheet'!H57,0) -> 765.88 | J47: =IFERROR('Data Sheet'!I57,0) -> 766.02 | ... L47: =IFERROR('Data Sheet'!K57,0) -> 736
B48: Reserves | C48: =IFERROR('Data Sheet'!B58,0) -> 78273.23 | D48: =IFERROR('Data Sheet'!C58,0) -> 57382.67 | E48: =IFERROR('Data Sheet'!D58,0) -> 94748.69 | F48: =IFERROR('Data Sheet'!E58,0) -> 59500.34 | G48: =IFERROR('Data Sheet'!F58,0) -> 62358.99 | H48: =IFERROR('Data Sheet'!G58,0) -> 54480.91 | I48: =IFERROR('Data Sheet'!H58,0) -> 43795.36 | J48: =IFERROR('Data Sheet'!I58,0) -> 44555.77 | ... L48: =IFERROR('Data Sheet'!K58,0) -> 115408
A49: # | B49: Borrowings | C49: =IFERROR('Data Sheet'!B59,0) -> 69359.96 | D49: =IFERROR('Data Sheet'!C59,0) -> 78603.98 | E49: =IFERROR('Data Sheet'!D59,0) -> 88950.47 | F49: =IFERROR('Data Sheet'!E59,0) -> 106175.34 | G49: =IFERROR('Data Sheet'!F59,0) -> 124787.64 | H49: =IFERROR('Data Sheet'!G59,0) -> 142130.57 | I49: =IFERROR('Data Sheet'!H59,0) -> 146449.03 | J49: =IFERROR('Data Sheet'!I59,0) -> 134113.44 | ... L49: =IFERROR('Data Sheet'!K59,0) -> 71540
B50: Other Liabilities | C50: =IFERROR('Data Sheet'!B60,0) -> 114871.75 | D50: =IFERROR('Data Sheet'!C60,0) -> 135914.49 | E50: =IFERROR('Data Sheet'!D60,0) -> 142813.43 | F50: =IFERROR('Data Sheet'!E60,0) -> 139348.59 | G50: =IFERROR('Data Sheet'!F60,0) -> 132313.22 | H50: =IFERROR('Data Sheet'!G60,0) -> 144192.62 | I50: =IFERROR('Data Sheet'!H60,0) -> 138051.22 | J50: =IFERROR('Data Sheet'!I60,0) -> 155239.2 | ... L50: =IFERROR('Data Sheet'!K60,0) -> 189289
B51: Total Liabilities | C51: =IFERROR('Data Sheet'!B61,0) -> 263184.12 | D51: =IFERROR('Data Sheet'!C61,0) -> 272580.36 | E51: =IFERROR('Data Sheet'!D61,0) -> 327191.81 | F51: =IFERROR('Data Sheet'!E61,0) -> 305703.49 | G51: =IFERROR('Data Sheet'!F61,0) -> 320179.39 | H51: =IFERROR('Data Sheet'!G61,0) -> 341569.91 | I51: =IFERROR('Data Sheet'!H61,0) -> 329061.49 | J51: =IFERROR('Data Sheet'!I61,0) -> 334674.43 | ... L51: =IFERROR('Data Sheet'!K61,0) -> 376973
B53: Fixed Assets Net Block | C53: =IFERROR('Data Sheet'!B62,0) -> 107231.76 | D53: =IFERROR('Data Sheet'!C62,0) -> 95944.08 | E53: =IFERROR('Data Sheet'!D62,0) -> 121413.86 | F53: =IFERROR('Data Sheet'!E62,0) -> 111234.47 | G53: =IFERROR('Data Sheet'!F62,0) -> 127107.14 | H53: =IFERROR('Data Sheet'!G62,0) -> 138707.61 | I53: =IFERROR('Data Sheet'!H62,0) -> 138855.45 | J53: =IFERROR('Data Sheet'!I62,0) -> 132079.76 | ... L53: =IFERROR('Data Sheet'!K62,0) -> 115697
B54: Capital Work in Progress | C54: =IFERROR('Data Sheet'!B63,0) -> 25918.94 | D54: =IFERROR('Data Sheet'!C63,0) -> 33698.84 | E54: =IFERROR('Data Sheet'!D63,0) -> 40033.5 | F54: =IFERROR('Data Sheet'!E63,0) -> 31883.84 | G54: =IFERROR('Data Sheet'!F63,0) -> 35622.29 | H54: =IFERROR('Data Sheet'!G63,0) -> 20963.93 | I54: =IFERROR('Data Sheet'!H63,0) -> 10251.09 | J54: =IFERROR('Data Sheet'!I63,0) -> 14274.5 | ... L54: =IFERROR('Data Sheet'!K63,0) -> 65806
B55: Investments | C55: =IFERROR('Data Sheet'!B64,0) -> 23767.02 | D55: =IFERROR('Data Sheet'!C64,0) -> 20337.92 | E55: =IFERROR('Data Sheet'!D64,0) -> 20812.75 | F55: =IFERROR('Data Sheet'!E64,0) -> 15770.72 | G55: =IFERROR('Data Sheet'!F64,0) -> 16308.48 | H55: =IFERROR('Data Sheet'!G64,0) -> 24620.28 | I55: =IFERROR('Data Sheet'!H64,0) -> 29379.53 | J55: =IFERROR('Data Sheet'!I64,0) -> 26379.16 | ... L55: =IFERROR('Data Sheet'!K64,0) -> 35656
B56: Other Assets | C56: =IFERROR('Data Sheet'!B65-SUM('Data Sheet'!B67:B69),0) -> 29579.36 | D56: =IFERROR('Data Sheet'!C65-SUM('Data Sheet'!C67:C69),0) -> 37360.78 | E56: =IFERROR('Data Sheet'!D65-SUM('Data Sheet'!D67:D69),0) -> 48286.86 | F56: =IFERROR('Data Sheet'!E65-SUM('Data Sheet'!E67:E69),0) -> 56155.74 | G56: =IFERROR('Data Sheet'!F65-SUM('Data Sheet'!F67:F69),0) -> 58784.94 | H56: =IFERROR('Data Sheet'!G65-SUM('Data Sheet'!G67:G69),0) -> 61717.96 | I56: =IFERROR('Data Sheet'!H65-SUM('Data Sheet'!H67:H69),0) -> 62223.77 | J56: =IFERROR('Data Sheet'!I65-SUM('Data Sheet'!I67:I69),0) -> 68432.09 | ... L56: =IFERROR('Data Sheet'!K65-SUM('Data Sheet'!K67:K69),0) -> 58463
B57: Total Non Current Assets | C57: =IFERROR(SUM(C53:C56),0) -> 186497.08 | D57: =IFERROR(SUM(D53:D56),0) -> 187341.62 | E57: =IFERROR(SUM(E53:E56),0) -> 230546.97 | F57: =IFERROR(SUM(F53:F56),0) -> 215044.77 | G57: =IFERROR(SUM(G53:G56),0) -> 237822.85 | H57: =IFERROR(SUM(H53:H56),0) -> 246009.78 | I57: =IFERROR(SUM(I53:I56),0) -> 240709.84 | J57: =IFERROR(SUM(J53:J56),0) -> 241165.51 | ... L57: =IFERROR(SUM(L53:L56),0) -> 275622
...

Sheet Financials>

Sheet Data Room>

Sheet Data Sheet
A1: COMPANY NAME | B1: TATA MOTORS LTD | E1: =IF(B2<>B3, "A NEW VERSION OF THE WORKSHEET IS AVAILABLE", "")
A2: LATEST VERSION | B2: 2.1 | E2: PLEASE DO NOT MAKE ANY CHANGES TO THIS SHEET
A3: CURRENT VERSION | B3: 2.1
A5: META
A6: Number of shares | B6: =IF(B9>0, B9/B8, 0) -> 368.17104
A7: Face Value | B7: 2
A8: Current Price | B8: 680.25
A9: Market Capitalization | B9: 250448.35
A15: PROFIT & LOSS
A16: Report Date | B16: 42460 | C16: 42825 | D16: 43190 | E16: 43555 | F16: 43921 | G16: 44286 | H16: 44651 | I16: 45016 | J16: 45382 | K16: 45747
A17: Sales | B17: 273045.6 | C17: 269692.51 | D17: 291550.48 | E17: 301938.4 | F17: 261067.97 | G17: 249794.75 | H17: 278453.62 | I17: 345966.97 | J17: 434016 | K17: 439695
A18: Raw Material Cost | B18: 166134.01 | C18: 173294.08 | D18: 187896.58 | E18: 194267.91 | F18: 164899.82 | G18: 153607.36 | H18: 179295.33 | I18: 231251.26 | J18: 274321 | K18: 268950
A19: Change in Inventory | B19: 2750.99 | C19: 7399.92 | D19: 2046.58 | E19: -2053.28 | F19: -2231.19 | G19: -4684.16 | H19: -1590.49 | I19: 4781.62 | J19: 1566 | K19: -2836
A20: Power and Fuel | B20: 1143.63 | C20: 1159.82 | D20: 1308.08 | E20: 1585.93 | F20: 1264.95 | G20: 1112.87 | H20: 2178.29 | I20: 2513.33 | J20: 2189 | K20: 2443
A21: Other Mfr. Exp | B21: 12101.53 | C21: 10067.37 | D21: 10971.66 | E21: 11694.54 | F21: 11541.51 | G21: 8273.17 | H21: 9427.38 | I21: 11765.97 | J21: 17446 | K21: 18813
A22: Employee Cost | B22: 28880.89 | C22: 28332.89 | D22: 30300.09 | E22: 33243.87 | F22: 30438.6 | G22: 27648.48 | H22: 30808.52 | I22: 33654.7 | J22: 41990 | K22: 47767
A23: Selling and admin | B23: 21991.9 | C23: 30039.38 | D23: 31004.58 | E23: 32719.8 | F23: 29248.32 | G23: 23015.79 | H23: 29205.4 | I23: 34839.19 | J23: 42765 | K23: 47099
A24: Other Expenses | B24: 7149.38 | C24: 4610.2 | D24: 658.39 | E24: 1708.74 | F24: 3456.51 | G24: -834.51 | H24: 1228.12 | I24: 4908.34 | J24: -953 | K24: -3429
A25: Other Income | B25: -2669.62 | C25: 1869.1 | D25: 5932.73 | E25: -26686.25 | F25: 101.71 | G25: -11117.83 | H25: 2424.05 | I25: 6663.97 | J25: 4792 | K25: 11774
A26: Depreciation | B26: 16710.78 | C26: 17904.99 | D26: 21553.59 | E26: 23590.63 | F26: 21425.43 | G26: 23546.71 | H26: 24835.69 | I26: 24860.36 | J26: 27239 | K26: 23256
A27: Interest | B27: 4889.08 | C27: 4238.01 | D27: 4681.79 | E27: 5758.6 | F27: 7243.33 | G27: 8097.17 | H27: 9311.86 | I27: 10225.48 | J27: 7594 | K27: 5083
... A30: Net profit | B30: 11579.31 | C30: 7454.36 | D30: 8988.91 | E30: -28826.23 | F30: -12070.85 | G30: -13451.39 | H30: -11441.47 | I30: 2414.29 | J30: 31399 | K30: 27830
A31: Dividend Amount | B31: 67.92 | I31: 766.02 | J31: 2301 | K31: 2208
A40: Quarters
A41: Report Date | B41: 44926 | C41: 45016 | D41: 45107 | E41: 45199 | F41: 45291 | G41: 45382 | H41: 45473 | I41: 45565 | J41: 45657 | K41: 45747
A42: Sales | B42: 88488.59 | C42: 105932.35 | D42: 102236 | E42: 105129 | F42: 110577 | G42: 119033 | H42: 108048 | I42: 101450 | J42: 112608 | K42: 119503
A43: Expenses | B43: 77668.35 | C43: 92817.95 | D43: 89019 | E43: 91362 | F43: 95159 | G43: 102348 | H43: 92263 | I43: 89291 | J43: 100185 | K43: 102685
A44: Other Income | B44: 1129.98 | C44: 1452.86 | D44: 895 | E44: 1557 | F44: 1604 | G44: 1412 | H44: 1747 | I44: 1647 | J44: 1700 | K44: 1057
A45: Depreciation | B45: 6071.78 | C45: 7050.2 | D45: 6633 | E45: 6637 | F45: 6850 | G45: 7143 | H45: 6574 | I45: 6005 | J45: 5399 | K45: 5295
A46: Interest | B46: 2675.83 | C46: 2641.67 | D46: 2615 | E46: 2652 | F46: 2485 | G46: 1645 | H46: 2088 | I46: 2034 | J46: 1119 | K46: 1076
A47: Profit before tax | B47: 3202.61 | C47: 4875.39 | D47: 4864 | E47: 6035 | F47: 7687 | G47: 9309 | H47: 8870 | I47: 5767 | J47: 7605 | K47: 11504
A48: Tax | B48: 262.83 | C48: -620.65 | D48: 1563 | E48: 2203 | F48: 542 | G48: -8219 | H48: 3178 | I48: 2317 | J48: 2120 | K48: 2948
A49: Net profit | B49: 2957.71 | C49: 5407.79 | D49: 3203 | E49: 3764 | F49: 7025 | G49: 17407 | H49: 5566 | I49: 3343 | J49: 5406 | K49: 8470
A50: Operating Profit | B50: 10820.24 | C50: 13114.4 | D50: 13217 | E50: 13767 | F50: 15418 | G50: 16685 | H50: 15785 | I50: 12159 | J50: 12423 | K50: 16818
A55: BALANCE SHEET
A56: Report Date | B56: 42460 | C56: 42825 | D56: 43190 | E56: 43555 | F56: 43921 | G56: 44286 | H56: 44651 | I56: 45016 | J56: 45382 | K56: 45747
A57: Equity Share Capital | B57: 679.18 | C57: 679.22 | D57: 679.22 | E57: 679.22 | F57: 719.54 | G57: 765.81 | H57: 765.88 | I57: 766.02 | J57: 767 | K57: 736
A58: Reserves | B58: 78273.23 | C58: 57382.67 | D58: 94748.69 | E58: 59500.34 | F58: 62358.99 | G58: 54480.91 | H58: 43795.36 | I58: 44555.77 | J58: 84151 | K58: 115408
A59: Borrowings | B59: 69359.96 | C59: 78603.98 | D59: 88950.47 | E59: 106175.34 | F59: 124787.64 | G59: 142130.57 | H59: 146449.03 | I59: 134113.44 | J59: 107264 | K59: 71540
A60: Other Liabilities | B60: 114871.75 | C60: 135914.49 | D60: 142813.43 | E60: 139348.59 | F60: 132313.22 | G60: 144192.62 | H60: 138051.22 | I60: 155239.2 | J60: 177339 | K60: 189289
...

Sheet Cash Flow Data
C2: 41699 | D2: 42064 | E2: 42430 | F2: 42795 | G2: 43160 | H2: 43525 | I2: 43891 | J2: 44256 | K2: 44621 | L2: 44986 | M2: 45352 | N2: 45717
B3: Cash from Operating Activity - | C3: 36151 | D3: 35531 | E3: 37900 | F3: 30199 | G3: 23857 | H3: 18891 | I3: 26633 | J3: 29001 | K3: 14283 | L3: 35388 | M3: 67915 | N3: 63102
B4: Profit from operations | C4: 36303 | D4: 43397 | E4: 38626 | F4: 28840 | G4: 33312 | H4: 28771 | I4: 23352 | J4: 31198 | K4: 26943 | L4: 41694 | M4: 65106 | N4: 58937
B5: Receivables | C5: 445 | D5: -3179 | E5: -2223 | F5: -4152 | G5: -10688 | H5: -9109 | I5: 9950 | J5: -5505 | K5: 185 | L5: -2213 | M5: -1876 | N5: 3573
B6: Inventory | C6: -2853 | D6: -3692 | E6: -5743 | F6: -6621 | G6: -3560 | H6: 2069 | I6: 2326 | J6: 3814 | K6: 472 | L6: -5665 | M6: -7265 | N6: 2127
B7: Payables | C7: 4694 | D7: 3598 | E7: 3947 | F7: 9301 | G7: 7320 | H7: -4692 | I7: -8085 | J7: 5748 | K7: -7012 | L7: 6945 | M7: 13706 | N7: 1303
B8: Loans Advances | C8: 0 | D8: 0 | E8: -520 | F8: 0 | G8: 0 | H8: 0 | I8: 0 | J8: 0 | K8: 0 | L8: 0 | M8: 0 | N8: 0
B9: Other WC items | C9: 1870 | D9: -398 | E9: 5852 | F9: 4727 | G9: 494 | H9: 4512 | I9: 875 | J9: -4150 | K9: -4396 | L9: -2194 | M9: 2760 | N9: 1153
B10: Working capital changes | C10: 4157 | D10: -3672 | E10: 1313 | F10: 3254 | G10: -6434 | H10: -7221 | I10: 5065 | J10: -93 | K10: -10750 | L10: -3127 | M10: 7325 | N10: 8156
B11: Direct taxes | C11: -4308 | D11: -4194 | E11: -2040 | F11: -1895 | G11: -3021 | H11: -2659 | I11: -1785 | J11: -2105 | K11: -1910 | L11: -3179 | M11: -4516 | N11: -3991
B12: Cash from Investing Activity - | C12: -27991 | D12: -36232 | E12: -36694 | F12: -39571 | G12: -25139 | H12: -20878 | I12: -33115 | J12: -25672 | K12: -4444 | L12: -15417 | M12: -22781 | N12: -49982
B13: Fixed assets purchased | C13: -26975 | D13: -31962 | E13: -31503 | F13: -16072 | G13: -35079 | H13: -35304 | I13: -29702 | J13: -20205 | K13: -15168 | L13: -19230 | M13: -31414 | N13: -38042
B14: Fixed assets sold | C14: 50 | D14: 74 | E14: 59 | F14: 53 | G14: 30 | H14: 67 | I14: 171 | J14: 351 | K14: 230 | L14: 285 | M14: 231 | N14: 974
... B33: Net Cash Flow | C33: 4277 | D33: 4500 | E33: -2589 | F33: -3167 | G33: 730 | H33: 6843 | I33: -3092 | J33: 13232 | K33: 6459 | L33: -6272 | M33: 8128 | N33: -5666
